Workbook

Sheet Calendário 2026
A1: Carimbo de data/hora | B1: Município | C1: Faz parte de uma Região Turística? | D1: Nome do evento | E1: Descrição do evento (breve descrição) | F1: Lei estadual (se aplicada) | G1: Endereço do evento | H1: Site do Evento (se possuir) | I1: Mês de Realização do evento | J1: Data inicial do evento (data prevista) | K1: Data final do evento (data prevista) | L1: Horário do evento - Início (Horário previsto. Caso não tenha, deixar em branco) | M1: Horário do evento - Fim (Horário previsto. Caso não tenha, deixar em branco) | N1: Tipo de evento (consultar manual: clique aqui) | O1: Categoria (consultar manual: clique aqui) | P1: Faz parte das categorias abaixo? | Q1: O evento é ligado à | R1: Tipo de público | S1: Público esperado (somente números) | T1: Público da edição de 2025 (somente números) | U1: Público da edição de 2024 (somente números) | V1: Público da edição de 2023 (somente números) | W1: Órgão ou empresa organizadora | X1: Site para compra do ingresso (se possuir) | Y1: Contato para mais informações (email) | Z1: Acessibilidade Informe para qual deficiência o seu evento esta preparado para receber: | AA1: Acessibilidade O que o evento possui: | AB1: Acessibilidade Digital Acessibilidade digital no site do Evento: | AC1: Classificação etária | AD1: Regiões Administrativas | AE1: ID | AF1: CD_GEOCODIGO | AG1: CD_GEOCODMU | AH1: LONG | AI1: LAT | AJ1: ALT | AK1: GM_PONTO_sk
A2: 46002.489 | B2: BARRETOS | C2: Águas Sertanejas | D2: 71ª Festa do Peão de Boiadeiro de Barretos | E2: Realizada anualmente em Barretos (SP), a Festa do Peão de Barretos é o maior rodeio da América Latina. O evento reúne competições de montaria, apresentações musicais nacionais e internacionais, atividades culturais, gastronomia típica e eventos voltados à tradição sertaneja e ao agronegócio. | G2: Parque do Peão - Rodovia Brigadeiro Faria Lima, km 428 – Barretos/SP – CEP 14783-000 | H2: https://www.independentes.com.br/festadopeao/inicio | I2: Agosto | J2: 45889 | K2: 45899 | N2: Festa | O2: Artístico/Cultural/Folclórico | P2: Rodeio | Q2: Nehuma das opções acima | R2: Nacional | S2: 900000 | T2: 900000 | U2: 900000 | V2: 900000 | W2: Os Independentes | X2: www.barretos.totalacesso.com/ | Y2: turismo@independentes.com.br | Z2: Deficiência Fisica, Deficiência Visual, Deficiência Auditiva | AA2: Atendimento em Línguas de Sinais, Piso Tátil, Rampa, Braille, Banheiro Acessível, Portas Largas para PCR (Pessoa com cadeira de rodas) | AB2: Intérprete de Libras no site do evento | AC2: Indicado para maiores de 18 anos | AD2: =IFERROR(VLOOKUP(B2,'Regiões Administrativas'!$A$1:$B$646,2,0),"") -> Barretos | AE2: =IFERROR(VLOOKUP(Form_Responses[[#This Row],[Município]],'Regiões Administrativas'!$A$1:$I$646,3,0),"") -> 15545 | AF2: =IFERROR(VLOOKUP(Form_Responses[[#This Row],[Município]],'Regiões Administrativas'!$A$1:$I$646,4,0),"") -> 350550005000001 | AG2: =IFERROR(VLOOKUP(Form_Responses[[#This Row],[Município]],'Regiões Administrativas'!$A$1:$I$646,4,0),"") -> 350550005000001 | AH2: =IFERROR(VLOOKUP(B2,'Regiões Administrativas'!$A$1:$I$646,5,0),"") -> 3505500 | AI2: =IFERROR(VLOOKUP(B2,'Regiões Administrativas'!$A$1:$I$646,6,0),"") -> -48.567378 | AJ2: =IFERROR(VLOOKUP(B2,'Regiões Administrativas'!$A$1:$I$646,8,0),"") -> 537.6636 | AK2: =IFERROR(VLOOKUP(Form_Responses[[#This Row],[Município]],'Regiões Administrativas'!$A$1:$I$646,9,0),"") -> 1J6RD.n:?3O>
A3: 46002.559 | B3: BOITUVA | C3: Raízes do Interior Paulista | D3: Campeonato Brasileiro de Balonismo | E3: Campeonato Brasileiro de Balonismo | G3: Rua Benedito Rodrigues de Melo, s/n, no bairro Portal Ville Primavera/Azaleia | I3: Junho | N3: Campeonato/Torneio/Concurso | O3: Esportivo | P3: Nenhuma das opções acima | Q3: Nehuma das opções acima | R3: Nacional | S3: 45000 | T3: 40000 | U3: 37000 | V3: 30000 | W3: Prefeitura e Confederação Brasileira de Balonismo | Y3: felipealvim50@gmail.com | Z3: Não possui | AA3: Banheiro Acessível | AB3: Não possui | AC3: Livre | AD3: =IFERROR(VLOOKUP(B3,'Regiões Administrativas'!$A$1:$B$646,2,0),"") -> Sorocaba | AE3: =IFERROR(VLOOKUP(Form_Responses[[#This Row],[Município]],'Regiões Administrativas'!$A$1:$I$646,3,0),"") -> 15591 | AF3: =IFERROR(VLOOKUP(Form_Responses[[#This Row],[Município]],'Regiões Administrativas'!$A$1:$I$646,4,0),"") -> 350700105000001 | AG3: =IFERROR(VLOOKUP(Form_Responses[[#This Row],[Município]],'Regiões Administrativas'!$A$1:$I$646,4,0),"") -> 350700105000001 | AH3: =IFERROR(VLOOKUP(B3,'Regiões Administrativas'!$A$1:$I$646,5,0),"") -> 3507001 | AI3: =IFERROR(VLOOKUP(B3,'Regiões Administrativas'!$A$1:$I$646,6,0),"") -> -47.671473 | AJ3: =IFERROR(VLOOKUP(B3,'Regiões Administrativas'!$A$1:$I$646,8,0),"") -> 643.45961 | AK3: =IFERROR(VLOOKUP(Form_Responses[[#This Row],[Município]],'Regiões Administrativas'!$A$1:$I$646,9,0),"") -> 1J6tlW*483;>
A4: 46002.561 | B4: BOITUVA | C4: Raízes do Interior Paulista | D4: 19° Festival de Inverno | E4: Festival de Inverno | G4: Av. Pereira Ignacio, 101 - Res Primo, Boituva | I4: Julho | N4: Festival | O4: Artístico/Cultural/Folclórico | P4: Nenhuma das opções acima | Q4: Nehuma das opções acima | R4: Regional | S4: 30000 | T4: 27000 | U4: 23000 | V4: 20000 | W4: Prefeitura de Boituva | Y4: felipealvim50@gmail.com | Z4: Deficiência Fisica | AA4: Rampa, Elevador, Banheiro Acessível | AB4: Intérprete de Libras no site do evento | AC4: Livre | AD4: =IFERROR(VLOOKUP(B4,'Regiões Administrativas'!$A$1:$B$646,2,0),"") -> Sorocaba | AE4: =IFERROR(VLOOKUP(Form_Responses[[#This Row],[Município]],'Regiões Administrativas'!$A$1:$I$646,3,0),"") -> 15591 | AF4: =IFERROR(VLOOKUP(Form_Responses[[#This Row],[Município]],'Regiões Administrativas'!$A$1:$I$646,4,0),"") -> 350700105000001 | AG4: =IFERROR(VLOOKUP(Form_Responses[[#This Row],[Município]],'Regiões Administrativas'!$A$1:$I$646,4,0),"") -> 350700105000001 | AH4: =IFERROR(VLOOKUP(B4,'Regiões Administrativas'!$A$1:$I$646,5,0),"") -> 3507001 | AI4: =IFERROR(VLOOKUP(B4,'Regiões Administrativas'!$A$1:$I$646,6,0),"") -> -47.671473 | AJ4: =IFERROR(VLOOKUP(B4,'Regiões Administrativas'!$A$1:$I$646,8,0),"") -> 643.45961 | AK4: =IFERROR(VLOOKUP(Form_Responses[[#This Row],[Município]],'Regiões Administrativas'!$A$1:$I$646,9,0),"") -> 1J6tlW*483;>
A5: 46002.563 | B5: BOITUVA | C5: Raízes do Interior Paulista | D5: Boituvana 2026 | E5: Festival de Rodeiro | G5: Rua Benedito Mazuquim | I5: Setembro | N5: Festa | O5: Artístico/Cultural/Folclórico | P5: Rodeio | Q5: Nehuma das opções acima | R5: Regional | S5: 45000 | T5: 39000 | U5: 35000 | V5: 30000 | W5: Prefeitura de Boituva | Y5: felipealvim50@gmail.com | Z5: Não possui | AA5: Não possui | AB5: Não possui | AC5: Indicado para maiores de 14 anos | AD5: =IFERROR(VLOOKUP(B5,'Regiões Administrativas'!$A$1:$B$646,2,0),"") -> Sorocaba | AE5: =IFERROR(VLOOKUP(Form_Responses[[#This Row],[Município]],'Regiões Administrativas'!$A$1:$I$646,3,0),"") -> 15591 | AF5: =IFERROR(VLOOKUP(Form_Responses[[#This Row],[Município]],'Regiões Administrativas'!$A$1:$I$646,4,0),"") -> 350700105000001 | AG5: =IFERROR(VLOOKUP(Form_Responses[[#This Row],[Município]],'Regiões Administrativas'!$A$1:$I$646,4,0),"") -> 350700105000001 | AH5: =IFERROR(VLOOKUP(B5,'Regiões Administrativas'!$A$1:$I$646,5,0),"") -> 3507001 | AI5: =IFERROR(VLOOKUP(B5,'Regiões Administrativas'!$A$1:$I$646,6,0),"") -> -47.671473 | AJ5: =IFERROR(VLOOKUP(B5,'Regiões Administrativas'!$A$1:$I$646,8,0),"") -> 643.45961 | AK5: =IFERROR(VLOOKUP(Form_Responses[[#This Row],[Município]],'Regiões Administrativas'!$A$1:$I$646,9,0),"") -> 1J6tlW*483;>
A6: 46002.569 | B6: SÃO JOSÉ DO RIO PARDO | C6: Entre Rios, Serras e Cafés | D6: CARNAVAL 2026 | E6: O Carnaval de São José do Rio Pardo tem se consolidado como um dos maiores e melhores do interior do Estado de São Paulo. No último ano, o evento atraiu cerca de 5 mil pessoas por noite, demonstrando sua crescente relevância regional. A programação ocorre nas noites de sexta, sábado, domingo, segunda e terça-feira, além de matinê no domingo e na terça. Todos os dias contamos com uma atração de destaque nacional e outra de reconhecimento regional, garantindo diversidade, qualidade e grande participação do público. | G6: AVENIDA EUCLIDES DA CUNHA, S/N | I6: Fevereiro | J6: 46066 | K6: 46070 | N6: Festa | O6: Artístico/Cultural/Folclórico | P6: Carnaval | Q6: Nehuma das opções acima | R6: Nacional | S6: 25000 | T6: 20000 | U6: 15000 | V6: 15000 | W6: PREFEITURA MUNICIPAL | Y6: secturismocultura@saojosedoriopardo.sp.gov.br | Z6: Deficiência Fisica | AA6: Rampa, Banheiro Acessível, Portas Largas para PCR (Pessoa com cadeira de rodas) | AB6: Não possui | AC6: Indicado para maiores de 16 anos | AD6: =IFERROR(VLOOKUP(B6,'Regiões Administrativas'!$A$1:$B$646,2,0),"") -> Campinas | AE6: =IFERROR(VLOOKUP(Form_Responses[[#This Row],[Município]],'Regiões Administrativas'!$A$1:$I$646,3,0),"") -> 17171 | AF6: =IFERROR(VLOOKUP(Form_Responses[[#This Row],[Município]],'Regiões Administrativas'!$A$1:$I$646,4,0),"") -> 354970605000001 | AG6: =IFERROR(VLOOKUP(Form_Responses[[#This Row],[Município]],'Regiões Administrativas'!$A$1:$I$646,4,0),"") -> 354970605000001 | AH6: =IFERROR(VLOOKUP(B6,'Regiões Administrativas'!$A$1:$I$646,5,0),"") -> 3549706 | AI6: =IFERROR(VLOOKUP(B6,'Regiões Administrativas'!$A$1:$I$646,6,0),"") -> -46.888266 | AJ6: =IFERROR(VLOOKUP(B6,'Regiões Administrativas'!$A$1:$I$646,8,0),"") -> 718.57108 | AK6: =IFERROR(VLOOKUP(Form_Responses[[#This Row],[Município]],'Regiões Administrativas'!$A$1:$I$646,9,0),"") -> 1J6t_zRG<GU-
A7: 46002.58 | B7: SÃO JOSÉ DO RIO PARDO | C7: Entre Rios, Serras e Cafés | D7: SEMANA EUCLIDIANA | E7: A Semana Euclidiana é um evento cultural anual e o mais antigo do Brasil, realizado em São José do Rio Pardo (SP) entre 9 e 15 de agosto, para celebrar a vida e obra do escritor Euclides da Cunha, autor de Os Sertões, conectando sua memória à identidade local através de palestras, estudos, oficinas e atividades cívicas que envolvem a comunidade e pesquisadores. | G7: ACONTECE EM DIVERSOS LOCAIS DO MUNICIPIO DE ACORDO COM A PROGRAMAÇÃO | I7: Agosto | J7: 46243 | K7: 46249 | N7: Movimento | O7: Social/Cívico/Histórico | P7: Social/Cívico/Histórico | Q7: Nehuma das opções acima | R7: Nacional | S7: 15000 | T7: 15000 | U7: 13000 | V7: 11000 | W7: PREFEITURA MUNICIPAL DE SÃO JOSE DO RIO PARDO | Y7: secturismocultura@saojosedoriopardo.sp.gov.br | Z7: Deficiência Fisica, Deficiência Visual, Deficiência Auditiva | AA7: Atendimento em Línguas de Sinais, Rampa, Elevador, Banheiro Acessível, Portas Largas para PCR (Pessoa com cadeira de rodas) | AB7: Não possui | AC7: Livre | AD7: =IFERROR(VLOOKUP(B7,'Regiões Administrativas'!$A$1:$B$646,2,0),"") -> Campinas | AE7: =IFERROR(VLOOKUP(Form_Responses[[#This Row],[Município]],'Regiões Administrativas'!$A$1:$I$646,3,0),"") -> 17171 | AF7: =IFERROR(VLOOKUP(Form_Responses[[#This Row],[Município]],'Regiões Administrativas'!$A$1:$I$646,4,0),"") -> 354970605000001 | AG7: =IFERROR(VLOOKUP(Form_Responses[[#This Row],[Município]],'Regiões Administrativas'!$A$1:$I$646,4,0),"") -> 354970605000001 | AH7: =IFERROR(VLOOKUP(B7,'Regiões Administrativas'!$A$1:$I$646,5,0),"") -> 3549706 | AI7: =IFERROR(VLOOKUP(B7,'Regiões Administrativas'!$A$1:$I$646,6,0),"") -> -46.888266 | AJ7: =IFERROR(VLOOKUP(B7,'Regiões Administrativas'!$A$1:$I$646,8,0),"") -> 718.57108 | AK7: =IFERROR(VLOOKUP(Form_Responses[[#This Row],[Município]],'Regiões Administrativas'!$A$1:$I$646,9,0),"") -> 1J6t_zRG<GU-
A8: 46002.617 | B8: SANTA SALETE | C8: Entre Rios | D8: FESTIVIDADES DE ANIVERSÁRIO DO MUNICIPIO | E8: FESTIVIDADE ANIVERSÁRIO DO MUNICIPIO COM DESFILI CIVICO, ATRAÇÕES CULTURAIS, SHOW SERTANEJOS, EVENTOS ESPORTIVOS, CAVALGADA. | F8: NÃO | G8: AVENIDA XV DE NOVEMBRO CENTRO | H8: www.prefeituramunicipaldesantasalete.sp.gov.br | I8: Março | J8: 46103 | K8: 46110 | N8: Aniversário | O8: Social/Cívico/Histórico | P8: Social/Cívico/Histórico | Q8: Nehuma das opções acima | R8: Regional | S8: 4000 | T8: 3000 | U8: 2500 | V8: 1500 | W8: secretaria de cultura do município | Y8: esporte@santasalete.sp.gov.br | Z8: Deficiência Fisica | AA8: Rampa, Banheiro Acessível | AB8: Não possui | AC8: Livre | AD8: =IFERROR(VLOOKUP(B8,'Regiões Administrativas'!$A$1:$B$646,2,0),"") -> São José do Rio Preto | AE8: =IFERROR(VLOOKUP(Form_Responses[[#This Row],[Município]],'Regiões Administrativas'!$A$1:$I$646,3,0),"") -> 17107 | AF8: =IFERROR(VLOOKUP(Form_Responses[[#This Row],[Município]],'Regiões Administrativas'!$A$1:$I$646,4,0),"") -> 354765005000001 | AG8: =IFERROR(VLOOKUP(Form_Responses[[#This Row],[Município]],'Regiões Administrativas'!$A$1:$I$646,4,0),"") -> 354765005000001 | AH8: =IFERROR(VLOOKUP(B8,'Regiões Administrativas'!$A$1:$I$646,5,0),"") -> 3547650 | AI8: =IFERROR(VLOOKUP(B8,'Regiões Administrativas'!$A$1:$I$646,6,0),"") -> -50.688462 | AJ8: =IFERROR(VLOOKUP(B8,'Regiões Administrativas'!$A$1:$I$646,8,0),"") -> 443.15183 | AK8: =IFERROR(VLOOKUP(Form_Responses[[#This Row],[Município]],'Regiões Administrativas'!$A$1:$I$646,9,0),"") -> 1J6R@Sgi2B<f
A9: 46002.621 | B9: ITAPORANGA | C9: Angra Paulista | D9: ITAPÔ FOILIA - CARNAVAL DE RUA DE ITAPORANGA | E9: O Itapô Folia é o tradicional carnaval de rua de Itaporanga, realizado de 13 a 15 de fevereiro na Praça João Abdallah, com entrada totalmente gratuita. O evento reúne famílias e visitantes de diversas cidades, oferecendo um ambiente acolhedor, alegre e repleto de cores e fantasias. A programação conta com bandas show típicas de carnaval, garantindo animação durante todas as noites. O espaço possui praça de alimentação completa, estrutura de banheiros e um sistema de segurança especializada, com monitoramento por câmeras em 100% da área do evento. Marcado pela organização e pelo clima familiar, o Itapô Folia se consolidou como um dos eventos mais aguardados da região, celebrando a cultura e a diversão de forma segura e acessível a todos. | F9: NÃO POSSUI | G9: PRAÇA JOÃO ABDALLAH | H9: SOMENTE PAGINAS OFICIAIS DA PREFEITURA MUNICIPAL | I9: Fevereiro | J9: 46066 | K9: 46068 | L9: 0.83333333 | M9: 0.083333333 | N9: Festa | O9: Artístico/Cultural/Folclórico | P9: Carnaval | Q9: Nehuma das opções acima | R9: Regional | S9: 10000 | T9: 9000 | U9: 8000 | V9: 6500 | W9: PREFEITURA MUNICIPAAL | X9: ENTRADA FRANCA | Y9: 15 3565 1397 | Z9: Deficiência Fisica | AA9: Rampa, Banheiro Acessível | AB9: Não possui | AC9: Livre | AD9: =IFERROR(VLOOKUP(B9,'Regiões Administrativas'!$A$1:$B$646,2,0),"") -> Itapeva | AE9: =IFERROR(VLOOKUP(Form_Responses[[#This Row],[Município]],'Regiões Administrativas'!$A$1:$I$646,3,0),"") -> 16121 | AF9: =IFERROR(VLOOKUP(Form_Responses[[#This Row],[Município]],'Regiões Administrativas'!$A$1:$I$646,4,0),"") -> 352280205000001 | AG9: =IFERROR(VLOOKUP(Form_Responses[[#This Row],[Município]],'Regiões Administrativas'!$A$1:$I$646,4,0),"") -> 352280205000001 | AH9: =IFERROR(VLOOKUP(B9,'Regiões Administrativas'!$A$1:$I$646,5,0),"") -> 3522802 | AI9: =IFERROR(VLOOKUP(B9,'Regiões Administrativas'!$A$1:$I$646,6,0),"") -> -49.484396 | AJ9: =IFERROR(VLOOKUP(B9,'Regiões Administrativas'!$A$1:$I$646,8,0),"") -> 545.30365 | AK9: =IFERROR(VLOOKUP(Form_Responses[[#This Row],[Município]],'Regiões Administrativas'!$A$1:$I$646,9,0),"") -> 1J6RXcH1e3dp
A10: 46002.628 | B10: ITAPORANGA | C10: Angra Paulista | D10: FESTIVIDADES INDIGENAS ALDEIA TEKOÁ PORÃ | E10: As Festividades Indígenas Tekoá Porã fazem parte do Mês dos Povos Indígenas e serão realizadas de 27 de abril a 1º de maio de 2026, na Aldeia Tekoá Porã, em Itaporanga/SP. O evento tem caráter cultural e educativo, oferecendo ao público uma imersão na tradição e no modo de vida indígena. Durante os dias de programação, a comunidade abre suas portas gratuitamente para visitas monitoradas pelos Guias Culturais da Aldeia. O evento recebe turistas, grupos escolares e visitantes de diversos municípios, somando milhares de pessoas ao longo das festividades. As atividades incluem cantos e danças tradicionais, rodas de conversa sobre cultura e costumes, visita à Oca Sagrada, Museu, Escola, trilhas e espaços comunitários. Na Arena Indígena, os participantes vivenciam esportes tradicionais como Uca-Uca, corrida de tora, cabo de guerra com cipó, arco e flecha e zarabatana. Há ainda exposição de artesanato e culinária típica. Reconhecido pela organização e pelo grande fluxo de visitantes, o evento reforça a valorização da cultura indígena e a importância do turismo cultural no município. | F10: não possui | G10: BAIRRO PRAINHA - ALDEIA TEKOÁ PORÃ | H10: NÃO POSSUI | I10: Abril | J10: 46139 | K10: 46143 | L10: 0.33333333 | M10: 0.75 | N10: Festa | O10: Artístico/Cultural/Folclórico | P10: Nenhuma das opções acima | Q10: Nehuma das opções acima | R10: Nacional | S10: 6000 | T10: 5500 | U10: 4800 | V10: 4000 | W10: ALDEIA TEKOÁ PORÃ | X10: NÃO POSSUI | Y10: 15 3565 1397 | Z10: Deficiência Fisica | AA10: Não possui | AB10: Não possui | AC10: Livre | AD10: =IFERROR(VLOOKUP(B10,'Regiões Administrativas'!$A$1:$B$646,2,0),"") -> Itapeva | AE10: =IFERROR(VLOOKUP(Form_Responses[[#This Row],[Município]],'Regiões Administrativas'!$A$1:$I$646,3,0),"") -> 16121 | AF10: =IFERROR(VLOOKUP(Form_Responses[[#This Row],[Município]],'Regiões Administrativas'!$A$1:$I$646,4,0),"") -> 352280205000001 | AG10: =IFERROR(VLOOKUP(Form_Responses[[#This Row],[Município]],'Regiões Administrativas'!$A$1:$I$646,4,0),"") -> 352280205000001 | AH10: =IFERROR(VLOOKUP(B10,'Regiões Administrativas'!$A$1:$I$646,5,0),"") -> 3522802 | AI10: =IFERROR(VLOOKUP(B10,'Regiões Administrativas'!$A$1:$I$646,6,0),"") -> -49.484396 | AJ10: =IFERROR(VLOOKUP(B10,'Regiões Administrativas'!$A$1:$I$646,8,0),"") -> 545.30365 | AK10: =IFERROR(VLOOKUP(Form_Responses[[#This Row],[Município]],'Regiões Administrativas'!$A$1:$I$646,9,0),"") -> 1J6RXcH1e3dp
A11: 46002.64 | B11: SANTA SALETE | C11: Entre Rios | D11: FESTA JUNINA - SÃO PEDRO | E11: FESTA JUNINA DE LONGA TRADIÇÃO - ONDE ENVOLVE TODA COMUNIDADE NA PREPARAÇÃO. COM DANÇA TIPICAS DO PERIODO JUNINO, TERÇO A SÃO PEDRO, E MUITA COMIDA, AMENDOIM, PIPOCA, QUENTÃO ACHOCOLATADO, DOCES TIPICOS. TUDO DE GRAÇA PARA POPULAÇÃO E O TURISTA | G11: PRAÇA DA IGREJA MATRIZ RUA OSVALDO CRUZ - CENTRO | I11: Junho | J11: 46201 | K11: 46202 | L11: 0.79166667 | M11: 0.083333333 | N11: Festa | O11: Artístico/Cultural/Folclórico | P11: Festa Junina | Q11: Nehuma das opções acima | R11: Regional | S11: 3000 | T11: 2000 | U11: 1500 | V11: 1500 | W11: PREFEITURA MUNICIPAL DE SANTA SALETE | Y11: esporte@santasalete.sp.gov.br | Z11: Deficiência Fisica | AA11: Rampa, Banheiro Acessível | AB11: Não possui | AC11: Livre | AD11: =IFERROR(VLOOKUP(B11,'Regiões Administrativas'!$A$1:$B$646,2,0),"") -> São José do Rio Preto | AE11: =IFERROR(VLOOKUP(Form_Responses[[#This Row],[Município]],'Regiões Administrativas'!$A$1:$I$646,3,0),"") -> 17107 | AF11: =IFERROR(VLOOKUP(Form_Responses[[#This Row],[Município]],'Regiões Administrativas'!$A$1:$I$646,4,0),"") -> 354765005000001 | AG11: =IFERROR(VLOOKUP(Form_Responses[[#This Row],[Município]],'Regiões Administrativas'!$A$1:$I$646,4,0),"") -> 354765005000001 | AH11: =IFERROR(VLOOKUP(B11,'Regiões Administrativas'!$A$1:$I$646,5,0),"") -> 3547650 | AI11: =IFERROR(VLOOKUP(B11,'Regiões Administrativas'!$A$1:$I$646,6,0),"") -> -50.688462 | AJ11: =IFERROR(VLOOKUP(B11,'Regiões Administrativas'!$A$1:$I$646,8,0),"") -> 443.15183 | AK11: =IFERROR(VLOOKUP(Form_Responses[[#This Row],[Município]],'Regiões Administrativas'!$A$1:$I$646,9,0),"") -> 1J6R@Sgi2B<f
A12: 46002.657 | B12: AREIAS | C12: Vale Histórico | D12: Micareias | E12: Carnaval antecipado. Acontece há mais de 30 anos um fim de semana antes do carnaval oficial. Atrai folioes de SP, RJ e Sul de Minas. | G12: Praça 09 de Julho | I12: Fevereiro | J12: 46059 | K12: 46060 | L12: 0.83333333 | M12: 0.125 | N12: Festa | O12: Comercial/Promocional | P12: Carnaval | Q12: Nehuma das opções acima | R12: Regional | S12: 5000 | U12: 4500 | V12: 6000 | W12: Prefeitura Municipal de Areias | Y12: areiastur@gmail.com | Z12: Não possui | AA12: Não possui | AB12: Não possui | AC12: Livre | AD12: =IFERROR(VLOOKUP(B12,'Regiões Administrativas'!$A$1:$B$646,2,0),"") -> São José dos Campos | AE12: =IFERROR(VLOOKUP(Form_Responses[[#This Row],[Município]],'Regiões Administrativas'!$A$1:$I$646,3,0),"") -> 15465 | AF12: =IFERROR(VLOOKUP(Form_Responses[[#This Row],[Município]],'Regiões Administrativas'!$A$1:$I$646,4,0),"") -> 350350505000001 | AG12: =IFERROR(VLOOKUP(Form_Responses[[#This Row],[Município]],'Regiões Administrativas'!$A$1:$I$646,4,0),"") -> 350350505000001 | AH12: =IFERROR(VLOOKUP(B12,'Regiões Administrativas'!$A$1:$I$646,5,0),"") -> 3503505 | AI12: =IFERROR(VLOOKUP(B12,'Regiões Administrativas'!$A$1:$I$646,6,0),"") -> -44.699432 | AJ12: =IFERROR(VLOOKUP(B12,'Regiões Administrativas'!$A$1:$I$646,8,0),"") -> 534.09202 | AK12: =IFERROR(VLOOKUP(Form_Responses[[#This Row],[Município]],'Regiões Administrativas'!$A$1:$I$646,9,0),"") -> 1J6tSQUiW^Gf
A13: 46002.664 | B13: AREIAS | C13: Vale Histórico | D13: Carnaval Bloco a Bloco | E13: O Carnaval reuni vários blocos do município, que vendem seus abadas, atraem turistas da região em um programação vespertina e noturna. Utilizam de trio elétrico para desfile do bloco e seguem para a praça de eventos onde acontece a apresentação de bandas de carnaval. | G13: Praça Senhor Bom Jesus | I13: Fevereiro | J13: 46067 | K13: 46071 | L13: 0.83333333 | M13: 0.125 | N13: Festa | O13: Artístico/Cultural/Folclórico | P13: Carnaval | Q13: Nehuma das opções acima | R13: Regional | S13: 3000 | T13: 3000 | U13: 4000 | V13: 4000 | W13: Prefeitura Municipal de Areias | Y13: areiastur@gmail.com | Z13: Não possui | AA13: Não possui | AB13: Não possui | AC13: Livre | AD13: =IFERROR(VLOOKUP(B13,'Regiões Administrativas'!$A$1:$B$646,2,0),"") -> São José dos Campos | AE13: =IFERROR(VLOOKUP(Form_Responses[[#This Row],[Município]],'Regiões Administrativas'!$A$1:$I$646,3,0),"") -> 15465 | AF13: =IFERROR(VLOOKUP(Form_Responses[[#This Row],[Município]],'Regiões Administrativas'!$A$1:$I$646,4,0),"") -> 350350505000001 | AG13: =IFERROR(VLOOKUP(Form_Responses[[#This Row],[Município]],'Regiões Administrativas'!$A$1:$I$646,4,0),"") -> 350350505000001 | AH13: =IFERROR(VLOOKUP(B13,'Regiões Administrativas'!$A$1:$I$646,5,0),"") -> 3503505 | AI13: =IFERROR(VLOOKUP(B13,'Regiões Administrativas'!$A$1:$I$646,6,0),"") -> -44.699432 | AJ13: =IFERROR(VLOOKUP(B13,'Regiões Administrativas'!$A$1:$I$646,8,0),"") -> 534.09202 | AK13: =IFERROR(VLOOKUP(Form_Responses[[#This Row],[Município]],'Regiões Administrativas'!$A$1:$I$646,9,0),"") -> 1J6tSQUiW^Gf
A14: 46002.665 | B14: CABREÚVA | C14: Roteiro dos Bandeirantes | D14: Carnabreúva | E14: Este evento, geralmente é composto por cinco dias de festa começando na sexta-feira que antecede o feriado de carnaval e finalizando na terça feira. No evento estão incluídas cinco noites de festa, duas matinês com a tradicional Banda São Roque tocando marchinhas. | G14: Praça Comendador Martins, Centro - Cabreúva/SP | H14: www.cabreuva.sp.gov.br | I14: Fevereiro | J14: 45701 | K14: 45705 | L14: 0.58333333 | M14: 0 | N14: Festa | O14: Artístico/Cultural/Folclórico | P14: Carnaval | Q14: Nehuma das opções acima | R14: Regional | S14: 24000 | T14: 24000 | U14: 22000 | V14: 20000 | W14: Secretaria Municipal de Cultura, Turismo e Patrimônio Histórico de Cabreúva | Y14: sec.cultura@cabreuva.sp.gov.br | Z14: Deficiência Fisica | AA14: Piso Tátil, Rampa, Banheiro Acessível | AB14: Não possui | AC14: Livre | AD14: =IFERROR(VLOOKUP(B14,'Regiões Administrativas'!$A$1:$B$646,2,0),"") -> Campinas | AE14: =IFERROR(VLOOKUP(Form_Responses[[#This Row],[Município]],'Regiões Administrativas'!$A$1:$I$646,3,0),"") -> 15658 | AF14: =IFERROR(VLOOKUP(Form_Responses[[#This Row],[Município]],'Regiões Administrativas'!$A$1:$I$646,4,0),"") -> 350840505000001 | AG14: =IFERROR(VLOOKUP(Form_Responses[[#This Row],[Município]],'Regiões Administrativas'!$A$1:$I$646,4,0),"") -> 350840505000001 | AH14: =IFERROR(VLOOKUP(B14,'Regiões Administrativas'!$A$1:$I$646,5,0),"") -> 3508405 | AI14: =IFERROR(VLOOKUP(B14,'Regiões Administrativas'!$A$1:$I$646,6,0),"") -> -47.133658 | AJ14: =IFERROR(VLOOKUP(B14,'Regiões Administrativas'!$A$1:$I$646,8,0),"") -> 656.6031 | AK14: =IFERROR(VLOOKUP(Form_Responses[[#This Row],[Município]],'Regiões Administrativas'!$A$1:$I$646,9,0),"") -> 1J6tLv=^]h4>
A15: 46002.667 | B15: CABREÚVA | C15: Roteiro dos Bandeirantes | D15: Festival de Inverno de Cabreúva | E15: Evento que atrai um público entre 20 e 30 mil pessoas, é a maior festa realizada na cidade. As atrações musicais são grandes nomes do Rock nacional e a gastronomia fica por conta dos estabelecimentos do município, visando assim o incentivo ao comércio local. O evento geralmente ocorre em um final de semana. | G15: Praça Comendador Martins, Centro - Cabreúva/SP | H15: www.cabreuva.sp.gov.br | I15: Julho | J15: 46214 | K15: 46215 | L15: 0.45833333 | M15: 0 | N15: Festival | O15: Artístico/Cultural/Folclórico | P15: Nenhuma das opções acima | Q15: Nehuma das opções acima | R15: Nacional | S15: 30000 | T15: 28000 | U15: 30000 | V15: 26000 | W15: Secretaria Municipal de Cultura, Turismo e Patrimônio Histórico de Cabreúva | Y15: sec.cultura@cabreuva.sp.gov.br | Z15: Deficiência Fisica, Deficiência Visual, Não possui | AA15: Piso Tátil, Rampa, Banheiro Acessível | AB15: Não possui | AC15: Livre | AD15: =IFERROR(VLOOKUP(B15,'Regiões Administrativas'!$A$1:$B$646,2,0),"") -> Campinas | AE15: =IFERROR(VLOOKUP(Form_Responses[[#This Row],[Município]],'Regiões Administrativas'!$A$1:$I$646,3,0),"") -> 15658 | AF15: =IFERROR(VLOOKUP(Form_Responses[[#This Row],[Município]],'Regiões Administrativas'!$A$1:$I$646,4,0),"") -> 350840505000001 | AG15: =IFERROR(VLOOKUP(Form_Responses[[#This Row],[Município]],'Regiões Administrativas'!$A$1:$I$646,4,0),"") -> 350840505000001 | AH15: =IFERROR(VLOOKUP(B15,'Regiões Administrativas'!$A$1:$I$646,5,0),"") -> 3508405 | AI15: =IFERROR(VLOOKUP(B15,'Regiões Administrativas'!$A$1:$I$646,6,0),"") -> -47.133658 | AJ15: =IFERROR(VLOOKUP(B15,'Regiões Administrativas'!$A$1:$I$646,8,0),"") -> 656.6031 | AK15: =IFERROR(VLOOKUP(Form_Responses[[#This Row],[Município]],'Regiões Administrativas'!$A$1:$I$646,9,0),"") -> 1J6tLv=^]h4>
A16: 46002.669 | B16: AREIAS | C16: Vale Histórico | D16: Festival de Bandas e Fanfarras de Areias | E16: Reune varias bandas e fanfarras da região, onde cada uma tem um tempo estimado para apresentação. Em 2026 será a 6 edição. Esse evento tem como anfitriã a Banda Marcial Municipal de Areias, que leva o titulo de Tri campeã Sul-americana de Bandas e Fanfarras de Itapema SC. A Banda faz parte do projeto musica nas escolas. | G16: Praça Senhor Bom Jesus | I16: Dezembro | J16: 46369 | K16: 46369 | L16: 0.45833333 | M16: 0.83333333 | N16: Festival | O16: Artístico/Cultural/Folclórico | P16: Nenhuma das opções acima | Q16: Nehuma das opções acima | R16: Regional | S16: 2000 | T16: 2000 | U16: 0000 | V16: 2000 | W16: Prefeitura Municipal de Areias | X16: gratuito | Y16: areiastur@gmail.com | Z16: Não possui | AA16: Não possui | AB16: Não possui | AC16: Livre | AD16: =IFERROR(VLOOKUP(B16,'Regiões Administrativas'!$A$1:$B$646,2,0),"") -> São José dos Campos | AE16: =IFERROR(VLOOKUP(Form_Responses[[#This Row],[Município]],'Regiões Administrativas'!$A$1:$I$646,3,0),"") -> 15465 | AF16: =IFERROR(VLOOKUP(Form_Responses[[#This Row],[Município]],'Regiões Administrativas'!$A$1:$I$646,4,0),"") -> 350350505000001 | AG16: =IFERROR(VLOOKUP(Form_Responses[[#This Row],[Município]],'Regiões Administrativas'!$A$1:$I$646,4,0),"") -> 350350505000001 | AH16: =IFERROR(VLOOKUP(B16,'Regiões Administrativas'!$A$1:$I$646,5,0),"") -> 3503505 | AI16: =IFERROR(VLOOKUP(B16,'Regiões Administrativas'!$A$1:$I$646,6,0),"") -> -44.699432 | AJ16: =IFERROR(VLOOKUP(B16,'Regiões Administrativas'!$A$1:$I$646,8,0),"") -> 534.09202 | AK16: =IFERROR(VLOOKUP(Form_Responses[[#This Row],[Município]],'Regiões Administrativas'!$A$1:$I$646,9,0),"") -> 1J6tSQUiW^Gf
A17: 46002.674 | B17: IGARATÁ | C17: Entre Serras e Águas | D17: IGT23K + Feira Gastronômica | E17: A IGT23K (Igaratá 23k) é amplamente conhecida como a maior corrida de montanha do Brasil, realizada anualmente em Igaratá/SP, e em sua ultima edição recebeu mais de 3 mil atletas, além do publico que vem acompanhar a corrida. Na na mesma data o COMTUR promove evento gastronômico para atender população e visitantes com diversidade gastronômica e shows na Praça de Eventos. | F17: Não | G17: Largada : Praça Luiz Carlos Lourenço | H17: zbrevents.com.br | I17: Março | J17: 46103 | K17: 46104 | L17: 0.33333333 | N17: Campeonato/Torneio/Concurso | O17: Esportivo | P17: Nenhuma das opções acima | Q17: Nehuma das opções acima | R17: Nacional | S17: 6000 | T17: 5500 | U17: 4600 | V17: 6000 | W17: ZBR com apoio COMTUR e Município Igaratá | X17: zbrevents.com.br | Y17: turismo@igarata.sp.gov.br | Z17: Não possui | AA17: Não possui | AB17: Não possui | AC17: Indicado para maiores de 18 anos | AD17: =IFERROR(VLOOKUP(B17,'Regiões Administrativas'!$A$1:$B$646,2,0),"") -> São José dos Campos | AE17: =IFERROR(VLOOKUP(Form_Responses[[#This Row],[Município]],'Regiões Administrativas'!$A$1:$I$646,3,0),"") -> 16025 | AF17: =IFERROR(VLOOKUP(Form_Responses[[#This Row],[Município]],'Regiões Administrativas'!$A$1:$I$646,4,0),"") -> 352020205000001 | AG17: =IFERROR(VLOOKUP(Form_Responses[[#This Row],[Município]],'Regiões Administrativas'!$A$1:$I$646,4,0),"") -> 352020205000001 | AH17: =IFERROR(VLOOKUP(B17,'Regiões Administrativas'!$A$1:$I$646,5,0),"") -> 3520202 | AI17: =IFERROR(VLOOKUP(B17,'Regiões Administrativas'!$A$1:$I$646,6,0),"") -> -46.156314 | AJ17: =IFERROR(VLOOKUP(B17,'Regiões Administrativas'!$A$1:$I$646,8,0),"") -> 741.81313 | AK17: =IFERROR(VLOOKUP(Form_Responses[[#This Row],[Município]],'Regiões Administrativas'!$A$1:$I$646,9,0),"") -> 1J6tOGPM^=vp
A18: 46002.698 | B18: ITAÓCA | C18: Cavernas da Mata Atlântica | D18: Show da virada | E18: Réveillon, realizado na praça central, atraindo público de diversos municípios vizinhos e de outros estados, com número considerável de visitantes, com shows e diversas atrações para o público | F18: Não se aplica | G18: Rua professor Elias Lages de Magalhães, s/n, centro, Praça José Silva, CEP 18360015 | H18: Não possui | I18: Dezembro | J18: 46019 | K18: 46022 | M18: 0.20833333 | N18: Festa | O18: Social/Cívico/Histórico | P18: Réveillon (Ano Novo) | Q18: Nehuma das opções acima | R18: Nacional | S18: 2500 | T18: 2500 | U18: 1900 | V18: 1500 | W18: Prefeitura Municipal | X18: Não possui | Y18: pmitaoca@gmail.com | Z18: Deficiência Fisica | AA18: Piso Tátil, Rampa, Banheiro Acessível | AB18: Não possui | AC18: Livre | AD18: =IFERROR(VLOOKUP(B18,'Regiões Administrativas'!$A$1:$B$646,2,0),"") -> Itapeva | AE18: =IFERROR(VLOOKUP(Form_Responses[[#This Row],[Município]],'Regiões Administrativas'!$A$1:$I$646,3,0),"") -> 16090 | AF18: =IFERROR(VLOOKUP(Form_Responses[[#This Row],[Município]],'Regiões Administrativas'!$A$1:$I$646,4,0),"") -> 352215805000001 | AG18: =IFERROR(VLOOKUP(Form_Responses[[#This Row],[Município]],'Regiões Administrativas'!$A$1:$I$646,4,0),"") -> 352215805000001 | AH18: =IFERROR(VLOOKUP(B18,'Regiões Administrativas'!$A$1:$I$646,5,0),"") -> 3522158 | AI18: =IFERROR(VLOOKUP(B18,'Regiões Administrativas'!$A$1:$I$646,6,0),"") -> -48.842856 | AJ18: =IFERROR(VLOOKUP(B18,'Regiões Administrativas'!$A$1:$I$646,8,0),"") -> 170.3779 | AK18: =IFERROR(VLOOKUP(Form_Responses[[#This Row],[Município]],'Regiões Administrativas'!$A$1:$I$646,9,0),"") -> 1J6S8237rK;>
A19: 46002.701 | B19: PEDRO DE TOLEDO | C19: Caminhos da Mata Atlântica | D19: CAMPEONATO ANUAL DE CHURRASCO BARBECUE PEDRO DE TOLEDO | E19: Campeonato Brasileiro de Churrasco Barbecue em Pedro de Toledo com Show Musical, O Evento será realizado no nosso Município, com mais de 18 equipes. Projeto de Lei que já faz parte do Calendário anual do Município no Mês de Julho | F19: Projeto de Lei Aprovado Nº 1.601 de 28/02/2020 | G19: Centro de Eventos Comunitários de Pedro de Toledo-SP | I19: Junho | J19: 46193 | K19: 46194 | L19: 0.375 | M19: 0.875 | N19: Campeonato/Torneio/Concurso | O19: Gastronômico | P19: Nenhuma das opções acima | Q19: Nehuma das opções acima | R19: Nacional | S19: 4000 | W19: Prefeitura Municipal de Pedro de Toledo | Y19: turismo@pedrodetoledo.sp.gov.br | Z19: Deficiência Fisica, Deficiência Visual, Deficiência Auditiva | AA19: Banheiro Acessível, Balcão de atendimento com altura reduzida, Portas Largas para PCR (Pessoa com cadeira de rodas), Outro: | AB19: Não possui | AC19: Livre | AD19: =IFERROR(VLOOKUP(B19,'Regiões Administrativas'!$A$1:$B$646,2,0),"") -> Registro | AE19: =IFERROR(VLOOKUP(Form_Responses[[#This Row],[Município]],'Regiões Administrativas'!$A$1:$I$646,3,0),"") -> 16773 | AF19: =IFERROR(VLOOKUP(Form_Responses[[#This Row],[Município]],'Regiões Administrativas'!$A$1:$I$646,4,0),"") -> 353720605000001 | AG19: =IFERROR(VLOOKUP(Form_Responses[[#This Row],[Município]],'Regiões Administrativas'!$A$1:$I$646,4,0),"") -> 353720605000001 | AH19: =IFERROR(VLOOKUP(B19,'Regiões Administrativas'!$A$1:$I$646,5,0),"") -> 3537206 | AI19: =IFERROR(VLOOKUP(B19,'Regiões Administrativas'!$A$1:$I$646,6,0),"") -> -47.229076 | AJ19: =IFERROR(VLOOKUP(B19,'Regiões Administrativas'!$A$1:$I$646,8,0),"") -> 62.710276 | AK19: =IFERROR(VLOOKUP(Form_Responses[[#This Row],[Município]],'Regiões Administrativas'!$A$1:$I$646,9,0),"") -> 1J6U*=,UtcP>
A20: 46002.702 | B20: ITAÓCA | C20: Cavernas da Mata Atlântica | D20: Aniversário da cidade | E20: Festa em comemoração do aniversário da cidade, com shows, apresentações culturais, eventos esportivos e outros | G20: Praça José Silva, rua professor Elias Lages de Magalhães, s/n, centro | I20: Novembro | J20: 45979 | K20: 45983 | N20: Aniversário | O20: Social/Cívico/Histórico | P20: Social/Cívico/Histórico | Q20: Nehuma das opções acima | R20: Nacional | S20: 1500 | T20: 1500 | U20: 1000 | V20: 1000 | W20: Prefeitura Municipal | Y20: pmitaoca@gmail.com | Z20: Deficiência Fisica | AA20: Piso Tátil, Rampa, Banheiro Acessível | AB20: Não possui | AC20: Livre | AD20: =IFERROR(VLOOKUP(B20,'Regiões Administrativas'!$A$1:$B$646,2,0),"") -> Itapeva | AE20: =IFERROR(VLOOKUP(Form_Responses[[#This Row],[Município]],'Regiões Administrativas'!$A$1:$I$646,3,0),"") -> 16090 | AF20: =IFERROR(VLOOKUP(Form_Responses[[#This Row],[Município]],'Regiões Administrativas'!$A$1:$I$646,4,0),"") -> 352215805000001 | AG20: =IFERROR(VLOOKUP(Form_Responses[[#This Row],[Município]],'Regiões Administrativas'!$A$1:$I$646,4,0),"") -> 352215805000001 | AH20: =IFERROR(VLOOKUP(B20,'Regiões Administrativas'!$A$1:$I$646,5,0),"") -> 3522158 | AI20: =IFERROR(VLOOKUP(B20,'Regiões Administrativas'!$A$1:$I$646,6,0),"") -> -48.842856 | AJ20: =IFERROR(VLOOKUP(B20,'Regiões Administrativas'!$A$1:$I$646,8,0),"") -> 170.3779 | AK20: =IFERROR(VLOOKUP(Form_Responses[[#This Row],[Município]],'Regiões Administrativas'!$A$1:$I$646,9,0),"") -> 1J6S8237rK;>
A21: 46003.395 | B21: OLÍMPIA | C21: Águas Sertanejas | D21: Carnaval Olímpia Folia 2026 | E21: Considerado um dos maiores carnavais do noroeste paulista, o evento será realizado no estacionamento do Thermas dos Laranjais e espera receber 80 mil foliões durante quatro noites de shows. A entrada para a pista é gratuita e informações sobre a venda de camarotes serão divulgadas em breve. Além disso, a Praça da Matriz receberá desfile das escolas de samba e matinês. Os distritos de Ribeiro dos Santos e Baguaçu também serão palco de matinês e shows. | F21: DECRETO Nº 9.444, DE 18 DE FEVEREIRO DE 2025 | G21: Estacionamento do Thermas dos Laranjais - Av. do Folclore, 1543, Olímpia-SP | H21: https://www.turismo.olimpia.sp.gov.br/ | I21: Fevereiro | J21: 46066 | K21: 46069 | L21: 0.79166667 | M21: 0.99930556 | N21: Festa | O21: Artístico/Cultural/Folclórico | P21: Carnaval | Q21: Nehuma das opções acima | R21: Nacional | S21: 80000 | T21: 60000 | U21: 40000 | V21: 60000 | W21: Prefeitura Municipal de Olímpia | Y21: prefeitura@olimpia.sp.gov.br | Z21: Deficiência Fisica | AA21: Rampa, Banheiro Acessível, Balcão de atendimento com altura reduzida, Portas Largas para PCR (Pessoa com cadeira de rodas) | AB21: Áudio Descrição no site do evento, Legenda no site do evento | AC21: Livre | AD21: =IFERROR(VLOOKUP(B21,'Regiões Administrativas'!$A$1:$B$646,2,0),"") -> Barretos | AE21: =IFERROR(VLOOKUP(Form_Responses[[#This Row],[Município]],'Regiões Administrativas'!$A$1:$I$646,3,0),"") -> 16671 | AF21: =IFERROR(VLOOKUP(Form_Responses[[#This Row],[Município]],'Regiões Administrativas'!$A$1:$I$646,4,0),"") -> 353390805000001 | AG21: =IFERROR(VLOOKUP(Form_Responses[[#This Row],[Município]],'Regiões Administrativas'!$A$1:$I$646,4,0),"") -> 353390805000001 | AH21: =IFERROR(VLOOKUP(B21,'Regiões Administrativas'!$A$1:$I$646,5,0),"") -> 3533908 | AI21: =IFERROR(VLOOKUP(B21,'Regiões Administrativas'!$A$1:$I$646,6,0),"") -> -48.913492 | AJ21: =IFERROR(VLOOKUP(B21,'Regiões Administrativas'!$A$1:$I$646,8,0),"") -> 500.31554 | AK21: =IFERROR(VLOOKUP(Form_Responses[[#This Row],[Município]],'Regiões Administrativas'!$A$1:$I$646,9,0),"") -> 1J6RdQ4;ieE-
A22: 46003.409 | B22: PAULICÉIA | C22: Sol do Oeste | D22: Réveillon | E22: Baile show em praça pública, aberta ao público em geral, com queima de fogos | F22: n | G22: Praça da Amizade | H22: n | I22: Dezembro | J22: 46387 | K22: 46388 | L22: 0.89583333 | M22: 0.125 | N22: Festa | O22: Social/Cívico/Histórico | P22: Réveillon (Ano Novo) | Q22: Nehuma das opções acima | R22: Regional | S22: 4500 | T22: 4500 | U22: 4000 | V22: 4000 | W22: Município | X22: n | Y22: turismo@pauliceia.sp.gov.br | Z22: Deficiência Fisica | AA22: Rampa, Banheiro Acessível, Portas Largas para PCR (Pessoa com cadeira de rodas) | AB22: Não possui | AC22: Livre | AD22: =IFERROR(VLOOKUP(B22,'Regiões Administrativas'!$A$1:$B$646,2,0),"") -> Presidente Prudente | AE22: =IFERROR(VLOOKUP(Form_Responses[[#This Row],[Município]],'Regiões Administrativas'!$A$1:$I$646,3,0),"") -> 16749 | AF22: =IFERROR(VLOOKUP(Form_Responses[[#This Row],[Município]],'Regiões Administrativas'!$A$1:$I$646,4,0),"") -> 353640605000001 | AG22: =IFERROR(VLOOKUP(Form_Responses[[#This Row],[Município]],'Regiões Administrativas'!$A$1:$I$646,4,0),"") -> 353640605000001 | AH22: =IFERROR(VLOOKUP(B22,'Regiões Administrativas'!$A$1:$I$646,5,0),"") -> 3536406 | AI22: =IFERROR(VLOOKUP(B22,'Regiões Administrativas'!$A$1:$I$646,6,0),"") -> -51.84714 | AJ22: =IFERROR(VLOOKUP(B22,'Regiões Administrativas'!$A$1:$I$646,8,0),"") -> 294.97142 | AK22: =IFERROR(VLOOKUP(Form_Responses[[#This Row],[Município]],'Regiões Administrativas'!$A$1:$I$646,9,0),"") -> 1J6R_cv7:*h>
A23: 46003.41 | B23: ITANHAÉM | C23: Costa da Mata Atlântica | D23: Festa do Divino Espírito Santo | E23: Realizada há mais de 300 anos, a Festa do Divino tem programação repleta de costumes e envolve fiéis de todas as idades em momentos importantes da comemoração, como a Noite da Soca, Alvorada Festiva, Abertura do Império, Missa Solene, Encerramento do Sentenciou, Procissão do Divino Espírito Santo, entre outros. | G23: Praça Narciso de Andrade | I23: Maio | J23: 46165 | K23: 46180 | L23: 0.79166667 | M23: 0.97916667 | N23: Festa | O23: Religioso | P23: Religioso | Q23: Nehuma das opções acima | R23: Regional | S23: 15000 | T23: 15000 | U23: 14500 | V23: 14500 | W23: Prefeitura de Itanhaém | Y23: turismo@itanhaem.sp.gov.br | Z23: Deficiência Fisica, Deficiência Intelectual | AA23: Rampa | AB23: Não possui | AC23: Livre | AD23: =IFERROR(VLOOKUP(B23,'Regiões Administrativas'!$A$1:$B$646,2,0),"") -> Santos | AE23: =IFERROR(VLOOKUP(Form_Responses[[#This Row],[Município]],'Regiões Administrativas'!$A$1:$I$646,3,0),"") -> 16088 | AF23: =IFERROR(VLOOKUP(Form_Responses[[#This Row],[Município]],'Regiões Administrativas'!$A$1:$I$646,4,0),"") -> 352210905000001 | AG23: =IFERROR(VLOOKUP(Form_Responses[[#This Row],[Município]],'Regiões Administrativas'!$A$1:$I$646,4,0),"") -> 352210905000001 | AH23: =IFERROR(VLOOKUP(B23,'Regiões Administrativas'!$A$1:$I$646,5,0),"") -> 3522109 | AI23: =IFERROR(VLOOKUP(B23,'Regiões Administrativas'!$A$1:$I$646,6,0),"") -> -46.790991 | AJ23: =IFERROR(VLOOKUP(B23,'Regiões Administrativas'!$A$1:$I$646,8,0),"") -> 6.473843 | AK23: =IFERROR(VLOOKUP(Form_Responses[[#This Row],[Município]],'Regiões Administrativas'!$A$1:$I$646,9,0),"") -> 1J6U:\7bhJ?f
A24: 46003.414 | B24: PAULICÉIA | C24: Sol do Oeste | D24: Carnaval | E24: Bailes carnavalescos, aberto ao público, realizado em praça ao ar livre. | F24: n | G24: Praça da Amizade | H24: n | I24: Fevereiro | J24: 46066 | K24: 46070 | L24: 0.91666667 | M24: 0.125 | N24: Festa | O24: Artístico/Cultural/Folclórico | P24: Carnaval | Q24: Nehuma das opções acima | R24: Regional | S24: 5000 | T24: 4500 | U24: 4500 | V24: 4500 | W24: Município | X24: n | Y24: turismo@pauliceia.sp.gov.br | Z24: Deficiência Fisica | AA24: Rampa, Banheiro Acessível, Portas Largas para PCR (Pessoa com cadeira de rodas) | AB24: Não possui | AC24: Livre | AD24: =IFERROR(VLOOKUP(B24,'Regiões Administrativas'!$A$1:$B$646,2,0),"") -> Presidente Prudente | AE24: =IFERROR(VLOOKUP(Form_Responses[[#This Row],[Município]],'Regiões Administrativas'!$A$1:$I$646,3,0),"") -> 16749 | AF24: =IFERROR(VLOOKUP(Form_Responses[[#This Row],[Município]],'Regiões Administrativas'!$A$1:$I$646,4,0),"") -> 353640605000001 | AG24: =IFERROR(VLOOKUP(Form_Responses[[#This Row],[Município]],'Regiões Administrativas'!$A$1:$I$646,4,0),"") -> 353640605000001 | AH24: =IFERROR(VLOOKUP(B24,'Regiões Administrativas'!$A$1:$I$646,5,0),"") -> 3536406 | AI24: =IFERROR(VLOOKUP(B24,'Regiões Administrativas'!$A$1:$I$646,6,0),"") -> -51.84714 | AJ24: =IFERROR(VLOOKUP(B24,'Regiões Administrativas'!$A$1:$I$646,8,0),"") -> 294.97142 | AK24: =IFERROR(VLOOKUP(Form_Responses[[#This Row],[Município]],'Regiões Administrativas'!$A$1:$I$646,9,0),"") -> 1J6R_cv7:*h>
A25: 46003.418 | B25: PAULICÉIA | C25: Sol do Oeste | D25: CarnaCross | E25: Tradicional competição de motocross, que ocorre há 25 anos, sendo realizado na pista permanente de motocross existente no balneário municipal, onde o público pode apreciar além da competição, a prainha, churrasqueiras e amplo espaço para motor home e camping. A competição ocorre durante os dias do carnaval, sendo uma alternativa aos bailes carnavalescos. | F25: n | G25: Balneário Municipal. | H25: n | I25: Fevereiro | J25: 46067 | K25: 46069 | L25: 0.33333333 | M25: 0.83333333 | N25: Campeonato/Torneio/Concurso | O25: Esportivo | P25: Carnaval | Q25: Nehuma das opções acima | R25: Internacional | S25: 4000 | T25: 3800 | U25: 4500 | V25: 4500 | W25: Município | X25: n | Y25: turismo@pauliceia.sp.gov.br | Z25: Deficiência Fisica | AA25: Banheiro Acessível | AB25: Não possui | AC25: Livre | AD25: =IFERROR(VLOOKUP(B25,'Regiões Administrativas'!$A$1:$B$646,2,0),"") -> Presidente Prudente | AE25: =IFERROR(VLOOKUP(Form_Responses[[#This Row],[Município]],'Regiões Administrativas'!$A$1:$I$646,3,0),"") -> 16749 | AF25: =IFERROR(VLOOKUP(Form_Responses[[#This Row],[Município]],'Regiões Administrativas'!$A$1:$I$646,4,0),"") -> 353640605000001 | AG25: =IFERROR(VLOOKUP(Form_Responses[[#This Row],[Município]],'Regiões Administrativas'!$A$1:$I$646,4,0),"") -> 353640605000001 | AH25: =IFERROR(VLOOKUP(B25,'Regiões Administrativas'!$A$1:$I$646,5,0),"") -> 3536406 | AI25: =IFERROR(VLOOKUP(B25,'Regiões Administrativas'!$A$1:$I$646,6,0),"") -> -51.84714 | AJ25: =IFERROR(VLOOKUP(B25,'Regiões Administrativas'!$A$1:$I$646,8,0),"") -> 294.97142 | AK25: =IFERROR(VLOOKUP(Form_Responses[[#This Row],[Município]],'Regiões Administrativas'!$A$1:$I$646,9,0),"") -> 1J6R_cv7:*h>
A26: 46003.423 | B26: PAULICÉIA | C26: Sol do Oeste | D26: Cavalgada | E26: No mês de junho, ocorre os festejos em comemoração ao aniversário de emancipação do município, e uma das atrações, é a cavalgada, que já ocorre há 20 anos, terminando com um almoço entre os participantes. | F26: n | G26: via pública | H26: n | I26: Junho | J26: 46180 | K26: 46180 | L26: 0.3125 | M26: 0.625 | N26: Aniversário | O26: Rural | P26: Agropecuária | Q26: Nehuma das opções acima | R26: Regional | S26: 1500 | T26: 1400 | U26: 1400 | V26: 1400 | W26: Município | X26: n | Y26: turismo@pauliceia.sp.gov.br | Z26: Não possui | AA26: Não possui | AB26: Não possui | AC26: Livre | AD26: =IFERROR(VLOOKUP(B26,'Regiões Administrativas'!$A$1:$B$646,2,0),"") -> Presidente Prudente | AE26: =IFERROR(VLOOKUP(Form_Responses[[#This Row],[Município]],'Regiões Administrativas'!$A$1:$I$646,3,0),"") -> 16749 | AF26: =IFERROR(VLOOKUP(Form_Responses[[#This Row],[Município]],'Regiões Administrativas'!$A$1:$I$646,4,0),"") -> 353640605000001 | AG26: =IFERROR(VLOOKUP(Form_Responses[[#This Row],[Município]],'Regiões Administrativas'!$A$1:$I$646,4,0),"") -> 353640605000001 | AH26: =IFERROR(VLOOKUP(B26,'Regiões Administrativas'!$A$1:$I$646,5,0),"") -> 3536406 | AI26: =IFERROR(VLOOKUP(B26,'Regiões Administrativas'!$A$1:$I$646,6,0),"") -> -51.84714 | AJ26: =IFERROR(VLOOKUP(B26,'Regiões Administrativas'!$A$1:$I$646,8,0),"") -> 294.97142 | AK26: =IFERROR(VLOOKUP(Form_Responses[[#This Row],[Município]],'Regiões Administrativas'!$A$1:$I$646,9,0),"") -> 1J6R_cv7:*h>
A27: 46003.427 | B27: TEODORO SAMPAIO | C27: Pontal Paulista | D27: Folia de Reis | E27: A Folia de Reis é uma celebração da Igreja Católica que rememora a visita dos três reis magos ao menino Jesus após seu nascimento. Trata-se de uma manifestação integrante do folclore brasileiro, realizada entre 24de dezembro, véspera do Natal, e 6 de janeiro, Dia de Reis. No município de Teodoro Sampaio, essa festa folclórica e cultural acontece há 39 anos. | G27: Assentamento Ribeirão Bonito | H27: sites.google.com/view/sec-turismocultura | I27: Dezembro | J27: 46015 | K27: 46032 | L27: 0.95833333 | M27: 0.79166667 | N27: Movimento | O27: Artístico/Cultural/Folclórico | P27: Religioso | Q27: Nehuma das opções acima | R27: Nacional | S27: 2000 | T27: 2500 | U27: 2000 | V27: 1350 | W27: Comissão da Folia de Reis | Y27: turismo@pmteodorosampaio.sp.gov.br | Z27: Deficiência Fisica | AA27: Banheiro Acessível, Portas Largas para PCR (Pessoa com cadeira de rodas) | AB27: Não possui | AC27: Livre | AD27: =IFERROR(VLOOKUP(B27,'Regiões Administrativas'!$A$1:$B$646,2,0),"") -> Presidente Prudente | AE27: =IFERROR(VLOOKUP(Form_Responses[[#This Row],[Município]],'Regiões Administrativas'!$A$1:$I$646,3,0),"") -> 17369 | AF27: =IFERROR(VLOOKUP(Form_Responses[[#This Row],[Município]],'Regiões Administrativas'!$A$1:$I$646,4,0),"") -> 355430005000001 | AG27: =IFERROR(VLOOKUP(Form_Responses[[#This Row],[Município]],'Regiões Administrativas'!$A$1:$I$646,4,0),"") -> 355430005000001 | AH27: =IFERROR(VLOOKUP(B27,'Regiões Administrativas'!$A$1:$I$646,5,0),"") -> 3554300 | AI27: =IFERROR(VLOOKUP(B27,'Regiões Administrativas'!$A$1:$I$646,6,0),"") -> -52.171195 | AJ27: =IFERROR(VLOOKUP(B27,'Regiões Administrativas'!$A$1:$I$646,8,0),"") -> 352.74983 | AK27: =IFERROR(VLOOKUP(Form_Responses[[#This Row],[Município]],'Regiões Administrativas'!$A$1:$I$646,9,0),"") -> 1J6RhG:@,eW>
A28: 46003.441 | B28: PAULICÉIA | C28: Sol do Oeste | D28: Rodeio Show | E28: Nos dias que antecedem a data do aniversário do município, 29/06, ocorre o Rodeio show, com montarias em touros e shows artísticos todas as noites, culminando na noite do dia 28, com distribuição de pipoca, amendoim torrado e quentão para o público presente, e ainda a queima da fogueira gigante, e queima de fogos, tradição desde 1984. | F28: n | G28: Recinto de Rodeio | H28: n | I28: Junho | J28: 46200 | K28: 46201 | L28: 0.79166667 | M28: 0.1875 | N28: Aniversário | O28: Social/Cívico/Histórico | P28: Festa Junina | Q28: Nehuma das opções acima | R28: Nacional | S28: 30000 | T28: 26000 | U28: 24000 | V28: 22000 | W28: Município | X28: n | Y28: turismo@pauliceia.sp.gov.br | Z28: Deficiência Fisica | AA28: Rampa, Banheiro Acessível | AB28: Não possui | AC28: Livre | AD28: =IFERROR(VLOOKUP(B28,'Regiões Administrativas'!$A$1:$B$646,2,0),"") -> Presidente Prudente | AE28: =IFERROR(VLOOKUP(Form_Responses[[#This Row],[Município]],'Regiões Administrativas'!$A$1:$I$646,3,0),"") -> 16749 | AF28: =IFERROR(VLOOKUP(Form_Responses[[#This Row],[Município]],'Regiões Administrativas'!$A$1:$I$646,4,0),"") -> 353640605000001 | AG28: =IFERROR(VLOOKUP(Form_Responses[[#This Row],[Município]],'Regiões Administrativas'!$A$1:$I$646,4,0),"") -> 353640605000001 | AH28: =IFERROR(VLOOKUP(B28,'Regiões Administrativas'!$A$1:$I$646,5,0),"") -> 3536406 | AI28: =IFERROR(VLOOKUP(B28,'Regiões Administrativas'!$A$1:$I$646,6,0),"") -> -51.84714 | AJ28: =IFERROR(VLOOKUP(B28,'Regiões Administrativas'!$A$1:$I$646,8,0),"") -> 294.97142 | AK28: =IFERROR(VLOOKUP(Form_Responses[[#This Row],[Município]],'Regiões Administrativas'!$A$1:$I$646,9,0),"") -> 1J6R_cv7:*h>
A29: 46003.444 | B29: PAULICÉIA | C29: Sol do Oeste | D29: Chegada do Papai Noel | E29: Chegada do Papai Noel, com trem da alegria, personagens infantis, e inauguração da iluminação de decoração natalina. | F29: n | G29: Praça São Pedro | H29: n | I29: Dezembro | J29: 46362 | K29: 46362 | L29: 0.77083333 | M29: 0.89583333 | N29: Festa | O29: Artístico/Cultural/Folclórico | P29: Natal | Q29: Nehuma das opções acima | R29: Regional | S29: 4000 | T29: 4000 | U29: 4000 | V29: 4000 | W29: Município | X29: n | Y29: turismo@pauliceia.sp.gov.br | Z29: Deficiência Fisica | AA29: Rampa, Banheiro Acessível | AB29: Não possui | AC29: Livre | AD29: =IFERROR(VLOOKUP(B29,'Regiões Administrativas'!$A$1:$B$646,2,0),"") -> Presidente Prudente | AE29: =IFERROR(VLOOKUP(Form_Responses[[#This Row],[Município]],'Regiões Administrativas'!$A$1:$I$646,3,0),"") -> 16749 | AF29: =IFERROR(VLOOKUP(Form_Responses[[#This Row],[Município]],'Regiões Administrativas'!$A$1:$I$646,4,0),"") -> 353640605000001 | AG29: =IFERROR(VLOOKUP(Form_Responses[[#This Row],[Município]],'Regiões Administrativas'!$A$1:$I$646,4,0),"") -> 353640605000001 | AH29: =IFERROR(VLOOKUP(B29,'Regiões Administrativas'!$A$1:$I$646,5,0),"") -> 3536406 | AI29: =IFERROR(VLOOKUP(B29,'Regiões Administrativas'!$A$1:$I$646,6,0),"") -> -51.84714 | AJ29: =IFERROR(VLOOKUP(B29,'Regiões Administrativas'!$A$1:$I$646,8,0),"") -> 294.97142 | AK29: =IFERROR(VLOOKUP(Form_Responses[[#This Row],[Município]],'Regiões Administrativas'!$A$1:$I$646,9,0),"") -> 1J6R_cv7:*h>
A30: 46003.448 | B30: PAULICÉIA | C30: Sol do Oeste | D30: Festa do dia das Crianças | E30: Festa em comemoração ao dia das crianças, com distribuição de picolé, hot dog, algodão doce, e atrações circenses bem como brinquedos como cama elástica, escorregador, tudo montado na praça da amizade. | F30: n | G30: Praça da amizade | H30: n | I30: Outubro | L30: 0.33333333 | M30: 0.58333333 | N30: Festa | O30: Social/Cívico/Histórico | P30: Social/Cívico/Histórico | Q30: Nehuma das opções acima | R30: Municipal | S30: 1800 | T30: 1500 | U30: 1500 | V30: 1500 | W30: Município. | X30: n | Y30: turismo@pauliceia.sp.gov.br | Z30: Deficiência Fisica | AA30: Rampa, Banheiro Acessível | AB30: Não possui | AC30: Livre | AD30: =IFERROR(VLOOKUP(B30,'Regiões Administrativas'!$A$1:$B$646,2,0),"") -> Presidente Prudente | AE30: =IFERROR(VLOOKUP(Form_Responses[[#This Row],[Município]],'Regiões Administrativas'!$A$1:$I$646,3,0),"") -> 16749 | AF30: =IFERROR(VLOOKUP(Form_Responses[[#This Row],[Município]],'Regiões Administrativas'!$A$1:$I$646,4,0),"") -> 353640605000001 | AG30: =IFERROR(VLOOKUP(Form_Responses[[#This Row],[Município]],'Regiões Administrativas'!$A$1:$I$646,4,0),"") -> 353640605000001 | AH30: =IFERROR(VLOOKUP(B30,'Regiões Administrativas'!$A$1:$I$646,5,0),"") -> 3536406 | AI30: =IFERROR(VLOOKUP(B30,'Regiões Administrativas'!$A$1:$I$646,6,0),"") -> -51.84714 | AJ30: =IFERROR(VLOOKUP(B30,'Regiões Administrativas'!$A$1:$I$646,8,0),"") -> 294.97142 | AK30: =IFERROR(VLOOKUP(Form_Responses[[#This Row],[Município]],'Regiões Administrativas'!$A$1:$I$646,9,0),"") -> 1J6R_cv7:*h>
A31: 46003.46 | B31: OLÍMPIA | C31: Águas Sertanejas | D31: Aniversário da cidade de Olímpia | E31: O aniversário da cidade de Olímpia (SP) é comemorado em 2 de março, data em que se celebra sua fundação, comemorando 123 anos em 2026, com uma rica programação de shows, eventos cívicos e festividades que marcam a história da cidade e seu desenvolvimento, especialmente pelo turismo das águas termais | G31: Recinto do Folclore de Olímpia - Avenida Menina Moça, nº 800, Vila Hípica, Olímpia - SP, CEP 15407-050 | H31: olimpia.sp.gov.br | I31: Março | J31: 46083 | K31: 46083 | L31: 0.83333333 | M31: 0.99930556 | N31: Aniversário | O31: Social/Cívico/Histórico | P31: Social/Cívico/Histórico | Q31: Nehuma das opções acima | R31: Municipal | S31: 30000 | T31: 50000 | U31: 30000 | V31: 7000 | W31: Prefeitura da Estância Turística de Olímpia | Y31: prefeitura@olimpia.sp.gov.br | Z31: Deficiência Fisica | AA31: Atendimento em Línguas de Sinais, Rampa, Elevador, Banheiro Acessível, Balcão de atendimento com altura reduzida, Portas Largas para PCR (Pessoa com cadeira de rodas) | AB31: Áudio Descrição no site do evento, Legenda no site do evento | AC31: Livre | AD31: =IFERROR(VLOOKUP(B31,'Regiões Administrativas'!$A$1:$B$646,2,0),"") -> Barretos | AE31: =IFERROR(VLOOKUP(Form_Responses[[#This Row],[Município]],'Regiões Administrativas'!$A$1:$I$646,3,0),"") -> 16671 | AF31: =IFERROR(VLOOKUP(Form_Responses[[#This Row],[Município]],'Regiões Administrativas'!$A$1:$I$646,4,0),"") -> 353390805000001 | AG31: =IFERROR(VLOOKUP(Form_Responses[[#This Row],[Município]],'Regiões Administrativas'!$A$1:$I$646,4,0),"") -> 353390805000001 | AH31: =IFERROR(VLOOKUP(B31,'Regiões Administrativas'!$A$1:$I$646,5,0),"") -> 3533908 | AI31: =IFERROR(VLOOKUP(B31,'Regiões Administrativas'!$A$1:$I$646,6,0),"") -> -48.913492 | AJ31: =IFERROR(VLOOKUP(B31,'Regiões Administrativas'!$A$1:$I$646,8,0),"") -> 500.31554 | AK31: =IFERROR(VLOOKUP(Form_Responses[[#This Row],[Município]],'Regiões Administrativas'!$A$1:$I$646,9,0),"") -> 1J6RdQ4;ieE-
A32: 46003.484 | B32: TEODORO SAMPAIO | C32: Pontal Paulista | D32: Inauguração do Balneário Municipal | E32: Trio Elétrico e Banda de Axé | G32: Final da Avenida Manoel Guirado Segura-vicinal que liga ao balneário | H32: sites.google.com/view/sec-turismocultura | I32: Janeiro | J32: 42386 | K32: 46046 | N32: Feira/Exposição/Mostra | O32: Comercial/Promocional | P32: Nenhuma das opções acima | Q32: Nehuma das opções acima | R32: Regional | S32: 10000 | W32: Secretaria de Turismo e Cultura e secretaria de Esporte e Lazer do municipio de Teodoro Sampaio_SP | X32: entrada franca | Y32: turismo@pmteodorosampaio.sp.gov.br | Z32: Deficiência Fisica | AA32: Banheiro Acessível, Portas Largas para PCR (Pessoa com cadeira de rodas) | AB32: Não possui | AC32: Livre | AD32: =IFERROR(VLOOKUP(B32,'Regiões Administrativas'!$A$1:$B$646,2,0),"") -> Presidente Prudente | AE32: =IFERROR(VLOOKUP(Form_Responses[[#This Row],[Município]],'Regiões Administrativas'!$A$1:$I$646,3,0),"") -> 17369 | AF32: =IFERROR(VLOOKUP(Form_Responses[[#This Row],[Município]],'Regiões Administrativas'!$A$1:$I$646,4,0),"") -> 355430005000001 | AG32: =IFERROR(VLOOKUP(Form_Responses[[#This Row],[Município]],'Regiões Administrativas'!$A$1:$I$646,4,0),"") -> 355430005000001 | AH32: =IFERROR(VLOOKUP(B32,'Regiões Administrativas'!$A$1:$I$646,5,0),"") -> 3554300 | AI32: =IFERROR(VLOOKUP(B32,'Regiões Administrativas'!$A$1:$I$646,6,0),"") -> -52.171195 | AJ32: =IFERROR(VLOOKUP(B32,'Regiões Administrativas'!$A$1:$I$646,8,0),"") -> 352.74983 | AK32: =IFERROR(VLOOKUP(Form_Responses[[#This Row],[Município]],'Regiões Administrativas'!$A$1:$I$646,9,0),"") -> 1J6RhG:@,eW>
A33: 46003.497 | B33: ITAPECERICA DA SERRA | C33: Mananciais, Aventura, Artes e Negócios | D33: Festa da Primavera | E33: Evento familiar que acontece anualmente no município com caráter turístico e cultural; Realizado com o objetivo de promover a valorização das tradições locais, estimular a participação social e fomentar a economia criativa da região. A programação contempla atividades como apresentações artísticas, exposições de artesanatos, produtores locais, gastronomia e ações educativas voltadas à preservação ambiental. o evento integra o calendário municipal, contribuindo para o fortalecimento do turismo, para o desenvolvimento sociocultural e para ampliação de espaços de turismo e lazer. | G33: Praça da Fonte - Praça João Ferreira Domingues | H33: @turismoitapecerica | I33: Setembro | J33: 46291 | K33: 46292 | L33: 0.41666667 | M33: 0.95833333 | N33: Festa | O33: Artístico/Cultural/Folclórico | P33: Social/Cívico/Histórico | Q33: Nehuma das opções acima | R33: Regional | S33: 5000 | T33: 2500 | U33: 0 | V33: 0 | W33: Prefeitura Municipal de Itapecerica da Serra - Secretaria Municipal de Turismo | X33: evento gratuito | Y33: setur.itap@gmail.com | Z33: Deficiência Fisica, Deficiência Intelectual | AA33: Rampa, Banheiro Acessível | AB33: Não possui | AC33: Livre | AD33: =IFERROR(VLOOKUP(B33,'Regiões Administrativas'!$A$1:$B$646,2,0),"") -> RMSP | AE33: =IFERROR(VLOOKUP(Form_Responses[[#This Row],[Município]],'Regiões Administrativas'!$A$1:$I$646,3,0),"") -> 16095 | AF33: =IFERROR(VLOOKUP(Form_Responses[[#This Row],[Município]],'Regiões Administrativas'!$A$1:$I$646,4,0),"") -> 352220805000001 | AG33: =IFERROR(VLOOKUP(Form_Responses[[#This Row],[Município]],'Regiões Administrativas'!$A$1:$I$646,4,0),"") -> 352220805000001 | AH33: =IFERROR(VLOOKUP(B33,'Regiões Administrativas'!$A$1:$I$646,5,0),"") -> 3522208 | AI33: =IFERROR(VLOOKUP(B33,'Regiões Administrativas'!$A$1:$I$646,6,0),"") -> -46.850552 | AJ33: =IFERROR(VLOOKUP(B33,'Regiões Administrativas'!$A$1:$I$646,8,0),"") -> 905.95027 | AK33: =IFERROR(VLOOKUP(Form_Responses[[#This Row],[Município]],'Regiões Administrativas'!$A$1:$I$646,9,0),"") -> 1J6to^L]J:6f
A34: 46003.499 | B34: TEODORO SAMPAIO | C34: Pontal Paulista | D34: Aniversario Emancipação Politica Administrativa do Teodoro Sampaio | E34: Evento realizado com Show, desfile cívico, apresentação das bandas marciais regional, cidade dos infláveis, pipoca, algodão doce, refrigerante, dois dias de festa para a população municipal, regional e interestadual. | G34: Praça Antonio Evangelista da Silva, Avenida Cuiabá, n° 1544 | H34: sites.google.com/view/sec-turismocultura | I34: Março | J34: 46101 | K34: 46103 | L34: 0.375 | M34: 0.16666667 | N34: Aniversário | O34: Social/Cívico/Histórico | P34: Social/Cívico/Histórico | Q34: Nehuma das opções acima | R34: Nacional | S34: 10000 | T34: 5000 | U34: 2000 | V34: 800 | W34: Secretaria de Turismo e Cultura e Secretaria de Educação | Y34: turismo@pmteodorosampaio.sp.gov.br | Z34: Deficiência Fisica, Deficiência Intelectual | AA34: Banheiro Acessível, Portas Largas para PCR (Pessoa com cadeira de rodas) | AB34: Não possui | AC34: Livre | AD34: =IFERROR(VLOOKUP(B34,'Regiões Administrativas'!$A$1:$B$646,2,0),"") -> Presidente Prudente | AE34: =IFERROR(VLOOKUP(Form_Responses[[#This Row],[Município]],'Regiões Administrativas'!$A$1:$I$646,3,0),"") -> 17369 | AF34: =IFERROR(VLOOKUP(Form_Responses[[#This Row],[Município]],'Regiões Administrativas'!$A$1:$I$646,4,0),"") -> 355430005000001 | AG34: =IFERROR(VLOOKUP(Form_Responses[[#This Row],[Município]],'Regiões Administrativas'!$A$1:$I$646,4,0),"") -> 355430005000001 | AH34: =IFERROR(VLOOKUP(B34,'Regiões Administrativas'!$A$1:$I$646,5,0),"") -> 3554300 | AI34: =IFERROR(VLOOKUP(B34,'Regiões Administrativas'!$A$1:$I$646,6,0),"") -> -52.171195 | AJ34: =IFERROR(VLOOKUP(B34,'Regiões Administrativas'!$A$1:$I$646,8,0),"") -> 352.74983 | AK34: =IFERROR(VLOOKUP(Form_Responses[[#This Row],[Município]],'Regiões Administrativas'!$A$1:$I$646,9,0),"") -> 1J6RhG:@,eW>
